Workbook

Sheet Portfolio
A1: Project Performance Monitoring System Portfolio
A2: =TEXT(TODAY(),"dd mmmm yyyy") -> 13 April 2026
A4: No. | B4: Country | C4: Loan / Grant No. | D4: Project Number | E4: Project Officer | F4: Project Analyst | G4: Project Name | H4: Executing Agency | I4: Last Updated | J4: I. Basic Data | AF4: II. Project Performance Rating | AS4: III. Implementation Status | CB4: IV. Financial Management | CJ4: V. Output | CO4: VI. Safeguards
J5: Approval | K5: Signing | L5: Effective | M5: Original Closing | N5: Revised Closing | O5: Financial Closing | P5: PCR Due Date | Q5: Original Amount | R5: Net Effective | S5: Allocated | U5: Unallocated | W5: Committed | Y5: Uncommitted | AA5: Disbursed | AC5: Undisbursed | AF5: Output | AH5: Contract Award | AJ5: Disbursement | AL5: Financial Management | AN5: Safeguards | AP5: Overall | AS5: Contract Award (eOps Target) | AY5: Contract Award (Achievable Estimate) | BD5: Contract Award (Actual) | BJ5: Disbursement (eOps Target) | BP5: Disbursement (Achievable Estimate) | BU5: Disbursement (Actual) | CE5: Rating | CL5: Score | CM5: Rating | CO5: Indicators | CW5: Rating
K6: Signing | L6: Effective | M6: Original Closing | N6: Revised Closing | O6: Financial Closing | P6: PCR Due Date | Q6: Original Amount | R6: Net Effective | AF6: Current | AG6: Yearend | AH6: Current | AI6: Yearend | AJ6: Current | AK6: Yearend | AL6: Current | AM6: Yearend | AN6: Current | AO6: Yearend | AP6: Current | AQ6: Yearend | AS6: =YEAR($A$2)-1 -> 2025 | AT6: =_xlfn.CONCAT("Q1 ",$AS$6+1) -> Q1 2026 | AU6: =_xlfn.CONCAT("Q2 ",$AS$6+1) -> Q2 2026 | AV6: =_xlfn.CONCAT("Q3 ",$AS$6+1) -> Q3 2026 | AW6: =_xlfn.CONCAT("Q4 ",$AS$6+1) -> Q4 2026 | AX6: =YEAR($A$2) -> 2026 | AY6: =_xlfn.CONCAT("Q1 ",$AS$6+1) -> Q1 2026 | AZ6: =_xlfn.CONCAT("Q2 ",$AS$6+1) -> Q2 2026 | BA6: =_xlfn.CONCAT("Q3 ",$AS$6+1) -> Q3 2026 | BB6: =_xlfn.CONCAT("Q4 ",$AS$6+1) -> Q4 2026 | BC6: =YEAR($A$2) -> 2026 | BD6: =YEAR($A$2)-1 -> 2025 | BE6: =_xlfn.CONCAT("Q1 ",$AS$6+1) -> Q1 2026 | BF6: =_xlfn.CONCAT("Q2 ",$AS$6+1) -> Q2 2026 | BG6: =_xlfn.CONCAT("Q3 ",$AS$6+1) -> Q3 2026 | BH6: =_xlfn.CONCAT("Q4 ",$AS$6+1) -> Q4 2026 | BI6: =YEAR($A$2) -> 2026 | BJ6: =YEAR($A$2)-1 -> 2025 | BK6: =_xlfn.CONCAT("Q1 ",$AS$6+1) -> Q1 2026 | BL6: =_xlfn.CONCAT("Q2 ",$AS$6+1) -> Q2 2026 | BM6: =_xlfn.CONCAT("Q3 ",$AS$6+1) -> Q3 2026 | BN6: =_xlfn.CONCAT("Q4 ",$AS$6+1) -> Q4 2026 | BO6: =YEAR($A$2) -> 2026 | BP6: =_xlfn.CONCAT("Q1 ",$AS$6+1) -> Q1 2026 | BQ6: =_xlfn.CONCAT("Q2 ",$AS$6+1) -> Q2 2026 | BR6: =_xlfn.CONCAT("Q3 ",$AS$6+1) -> Q3 2026 | BS6: =_xlfn.CONCAT("Q4 ",$AS$6+1) -> Q4 2026 | BT6: =YEAR($A$2) -> 2026 | BU6: =YEAR($A$2)-1 -> 2025 | BV6: =_xlfn.CONCAT("Q1 ",$AS$6+1) -> Q1 2026 | BW6: =_xlfn.CONCAT("Q2 ",$AS$6+1) -> Q2 2026 | BX6: =_xlfn.CONCAT("Q3 ",$AS$6+1) -> Q3 2026 | BY6: =_xlfn.CONCAT("Q4 ",$AS$6+1) -> Q4 2026 | BZ6: =YEAR($A$2) -> 2026 | CG6: 1 | CH6: 2 | CI6: 3 | CJ6: 4 | CK6: 5 | CO6: 1 | CP6: 2 | CQ6: 3 | CR6: 4 | CS6: 5 | CT6: 6 | CU6: 7 | CV6: 8

Sheet <Approval numbers>
B2: Project Performance Monitoring Sheet
G4: Update as of
B6: Project Name: | I6: Sector/Subsector:
B7: Project Number | I7: Project Officer:
B8: Loan/Grant Number: | I8: Project Analyst:
B9: Executing/Implementing Agency: | I9: Project Document Link:
B10: ADB Administering Unit: | E10: If TRJM, date of project transfer: | I10: Project Handover Document Link:
A12: ~ | B12: A. Loan/Grant Basic Data
A13: ~ | B13: ADB Financing | C13: Government Financing | D13: Total ($ million equivalent) | F13: PCR Due Date | H13: Environment Category | I13: Involuntary Resettlement Category | J13: Indigenous People's Category | K13: Gender Category
F14: =IF(J18="-","",MAX(J18:J21)+365)
A15: ~
A16: ~ | B16: Product | C16: Source | D16: Approval | E16: Signing | F16: Effectivity | G16: Closing | I16: % Elapsed Time | J16: Financial Closing | K16: Amount | Y16: Remarks
A17: ~ | G17: Original | H17: Revised | K17: Original | L17: Net Effective | M17: Allocated | O17: Unallocated | Q17: Committed | S17: Uncommitted | U17: Disbursed | W17: Undisbursed
J18: =IF(ISBLANK(B18),"-",IF(H18="",G18+180,H18+180)) -> - | M18: =IF(ISBLANK($B18),0,SUMIFS($U$130:$U$144,$B$130:$B$144,$B18)) -> 0 | N18: =IF(ISBLANK($B18),0,(IF(ISBLANK($L18),IF($K18>0,M18/$K18,0),IF($L18>0,M18/$L18,0)))) -> 0 | O18: =IF(ISBLANK(B18),0,L18-SUMIFS($U$130:$U$144,$B$130:$B$144,$B18)) -> 0 | P18: =IF(ISBLANK(B18),0,(IF(ISBLANK(L18),IF(K18>0,O18/K18,0),IF(L18>0,O18/L18,0)))) -> 0 | Q18: =IF(ISBLANK($B18),0,SUMIFS($T$130:$T$144,$B$130:$B$144,$B18)) -> 0 | R18: =IF(ISBLANK($B18),0,(IF(ISBLANK($L18),IF($K18>0,Q18/$K18,0),IF($L18>0,M18/$L18,0)))) -> 0 | S18: =IF(ISBLANK(B18),0,L18-SUMIFS($T$130:$T$144,$B$130:$B$144,$B18)) -> 0 | T18: =IF(ISBLANK(B18),0,(IF(ISBLANK(L18),IF(K18>0,S18/K18,0),IF(L18>0,S18/L18,0)))) -> 0 | U18: =IF(ISBLANK($B18),0,SUMIFS($L$130:$L$144,$B$130:$B$144,$B18)) -> 0 | V18: =IF(ISBLANK(B18),0,(IF(ISBLANK(L18),IF(K18>0,U18/K18,0),IF(L18>0,U18/L18,0)))) -> 0 | W18: =IF(ISBLANK(B18),0,(IF(ISBLANK($L18),$K18-SUMIFS($B$130:$B$143,$L$130:$L$143,$B18),$L18-SUMIFS($L$130:$L$143,$B$130:$B$143,$B18)))) -> 0 | X18: =IF(ISBLANK(B18),0,IF(OR(ISBLANK(L18),L18=0),W18/K18,W18/L18)) -> 0
J19: =IF(ISBLANK(B19),"-",IF(H19="",G19+180,H19+180)) -> - | M19: =IF(ISBLANK($B19),0,SUMIFS($U$130:$U$144,$B$130:$B$144,$B19)) -> 0 | N19: =IF(ISBLANK($B19),0,(IF(ISBLANK($L19),IF($K19>0,M19/$K19,0),IF($L19>0,M19/$L19,0)))) -> 0 | O19: =IF(ISBLANK(B19),0,L19-SUMIFS($U$130:$U$144,$B$130:$B$144,$B19)) -> 0 | P19: =IF(ISBLANK(B19),0,(IF(ISBLANK(L19),IF(K19>0,O19/K19,0),IF(L19>0,O19/L19,0)))) -> 0 | Q19: =IF(ISBLANK($B19),0,SUMIFS($T$130:$T$144,$B$130:$B$144,$B19)) -> 0 | R19: =IF(ISBLANK($B19),0,(IF(ISBLANK($L19),IF($K19>0,Q19/$K19,0),IF($L19>0,M19/$L19,0)))) -> 0 | S19: =IF(ISBLANK(B19),0,L19-SUMIFS($T$130:$T$144,$B$130:$B$144,$B19)) -> 0 | T19: =IF(ISBLANK(B19),0,(IF(ISBLANK(L19),IF(K19>0,S19/K19,0),IF(L19>0,S19/L19,0)))) -> 0 | U19: =IF(ISBLANK($B19),0,SUMIFS($L$130:$L$144,$B$130:$B$144,$B19)) -> 0 | V19: =IF(ISBLANK(B19),0,(IF(ISBLANK(L19),IF(K19>0,U19/K19,0),IF(L19>0,U19/L19,0)))) -> 0 | W19: =IF(ISBLANK(B19),0,(IF(ISBLANK($L19),$K19-SUMIFS($B$130:$B$143,$L$130:$L$143,$B19),$L19-SUMIFS($L$130:$L$143,$B$130:$B$143,$B19)))) -> 0 | X19: =IF(ISBLANK(B19),0,IF(OR(ISBLANK(L19),L19=0),W19/K19,W19/L19)) -> 0
J20: =IF(ISBLANK(B20),"-",IF(H20="",G20+180,H20+180)) -> - | M20: =IF(ISBLANK($B20),0,SUMIFS($U$130:$U$144,$B$130:$B$144,$B20)) -> 0 | N20: =IF(ISBLANK($B20),0,(IF(ISBLANK($L20),IF($K20>0,M20/$K20,0),IF($L20>0,M20/$L20,0)))) -> 0 | O20: =IF(ISBLANK(B20),0,L20-SUMIFS($U$130:$U$144,$B$130:$B$144,$B20)) -> 0 | P20: =IF(ISBLANK(B20),0,(IF(ISBLANK(L20),IF(K20>0,O20/K20,0),IF(L20>0,O20/L20,0)))) -> 0 | Q20: =IF(ISBLANK($B20),0,SUMIFS($T$130:$T$144,$B$130:$B$144,$B20)) -> 0 | R20: =IF(ISBLANK($B20),0,(IF(ISBLANK($L20),IF($K20>0,Q20/$K20,0),IF($L20>0,M20/$L20,0)))) -> 0 | S20: =IF(ISBLANK(B20),0,L20-SUMIFS($T$130:$T$144,$B$130:$B$144,$B20)) -> 0 | T20: =IF(ISBLANK(B20),0,(IF(ISBLANK(L20),IF(K20>0,S20/K20,0),IF(L20>0,S20/L20,0)))) -> 0 | U20: =IF(ISBLANK($B20),0,SUMIFS($L$130:$L$144,$B$130:$B$144,$B20)) -> 0 | V20: =IF(ISBLANK(B20),0,(IF(ISBLANK(L20),IF(K20>0,U20/K20,0),IF(L20>0,U20/L20,0)))) -> 0 | W20: =IF(ISBLANK(B20),0,(IF(ISBLANK($L20),$K20-SUMIFS($B$130:$B$143,$L$130:$L$143,$B20),$L20-SUMIFS($L$130:$L$143,$B$130:$B$143,$B20)))) -> 0 | X20: =IF(ISBLANK(B20),0,IF(OR(ISBLANK(L20),L20=0),W20/K20,W20/L20)) -> 0
J21: =IF(ISBLANK(B21),"-",IF(H21="",G21+180,H21+180)) -> - | M21: =IF(ISBLANK($B21),0,SUMIFS($U$130:$U$144,$B$130:$B$144,$B21)) -> 0 | N21: =IF(ISBLANK($B21),0,(IF(ISBLANK($L21),IF($K21>0,M21/$K21,0),IF($L21>0,M21/$L21,0)))) -> 0 | O21: =IF(ISBLANK(B21),0,L21-SUMIFS($U$130:$U$144,$B$130:$B$144,$B21)) -> 0 | P21: =IF(ISBLANK(B21),0,(IF(ISBLANK(L21),IF(K21>0,O21/K21,0),IF(L21>0,O21/L21,0)))) -> 0 | Q21: =IF(ISBLANK($B21),0,SUMIFS($T$130:$T$144,$B$130:$B$144,$B21)) -> 0 | R21: =IF(ISBLANK($B21),0,(IF(ISBLANK($L21),IF($K21>0,Q21/$K21,0),IF($L21>0,M21/$L21,0)))) -> 0 | S21: =IF(ISBLANK(B21),0,L21-SUMIFS($T$130:$T$144,$B$130:$B$144,$B21)) -> 0 | T21: =IF(ISBLANK(B21),0,(IF(ISBLANK(L21),IF(K21>0,S21/K21,0),IF(L21>0,S21/L21,0)))) -> 0 | U21: =IF(ISBLANK($B21),0,SUMIFS($L$130:$L$144,$B$130:$B$144,$B21)) -> 0 | V21: =IF(ISBLANK(B21),0,(IF(ISBLANK(L21),IF(K21>0,U21/K21,0),IF(L21>0,U21/L21,0)))) -> 0 | W21: =IF(ISBLANK(B21),0,(IF(ISBLANK($L21),$K21-SUMIFS($B$130:$B$143,$L$130:$L$143,$B21),$L21-SUMIFS($L$130:$L$143,$B$130:$B$143,$B21)))) -> 0 | X21: =IF(ISBLANK(B21),0,IF(OR(ISBLANK(L21),L21=0),W21/K21,W21/L21)) -> 0
A22: ~ | J22: Total | K22: =SUM(K18:K21) -> 0 | L22: =SUM(IF(ISBLANK(L18),K18,L18),IF(ISBLANK(L19),K19,L19),IF(ISBLANK(L20),K20,L20),IF(ISBLANK(L21),K21,L21)) -> 0 | M22: =SUM(M18:M21) -> 0 | N22: =IF($L22>0,SUM(M18:M21)/$L22,0) -> 0 | O22: =SUM(O18:O21) -> 0 | P22: =IF(L22>0,SUM(O18:O21)/L22,0) -> 0 | Q22: =SUM(Q18:Q21) -> 0 | R22: =IF($L22>0,SUM(Q18:Q21)/$L22,0) -> 0 | S22: =SUM(S18:S21) -> 0 | T22: =IF(L22>0,SUM(S18:S21)/L22,0) -> 0 | U22: =SUM(U18:U21) -> 0 | V22: =IF($L22>0,SUM(U18:U21)/$L22,0) -> 0 | W22: =SUM(W18:W21) -> 0 | X22: =IF(L22>0,SUM(W18:W21)/L22,0) -> 0
A23: ~ | B23: B. Project Rating
A24: ~ | B24: Operation Project Rating
A25: ~ | B25: Parameters | C25: Outputs | D25: Contract Awards (%) | E25: Disbursement (%) | F25: Financial Management | G25: Safeguards | H25: Overall Rating
B26: Ratings | D26: =C39 -> 0 | E26: =C44 -> 0
B27: Reason (if FA or AR)
A28: ~
A29: ~ | B29: Consecutive Overall Project Rating
A30: ~ | B30: Validated | F30: Current
A31: ~ | B31: 2024, Q4 | C31: 2025, Q1 | D31: 2025, Q2 | E31: 2025, Q3 | F31: 2025, Q4
A33: ~
A34: ~ | B34: C. Contract Awards and Disbursements
A35: ~ | B35: CA | C35: Total Cumulative | D35: Q1 2025 | F35: Q2 2025 | H35: Q3 2025 | J35: Q4 2025 | L35: 2025 Total
A36: ~ | D36: eOps | E36: Committed | F36: eOps | G36: Committed | H36: eOps | I36: Committed | J36: eOps | K36: Committed | L36: eOps | M36: Committed
B37: Target
B38: Achievement
B39: (%) | C39: =IFERROR(C38/C37,0) -> 0 | D39: =IFERROR(D38/D37,0) -> 0 | E39: =IFERROR(D38/E37,0) -> 0 | F39: =IFERROR(F38/F37,0) -> 0 | G39: =IFERROR(F38/G37,0) -> 0 | H39: =IFERROR(H38/H37,0) -> 0 | I39: =IFERROR(H38/I37,0) -> 0 | J39: =IFERROR(J38/J37,0) -> 0 | K39: =IFERROR(J38/K37,0) -> 0 | L39: =IFERROR(L38/L37,0) -> 0 | M39: =IFERROR(L38/M37,0) -> 0
A40: ~ | B40: DB | C40: Total Cumulative | D40: Q1 2025 | F40: Q2 2025 | H40: Q3 2025 | J40: Q4 2025 | L40: 2025 Total
A41: ~ | D41: eOps | E41: Committed | F41: eOps | G41: Committed | H41: eOps | I41: Committed | J41: eOps | K41: Committed | L41: eOps | M41: Committed
B42: Target
B43: Achievement
B44: (%) | C44: =IFERROR(C43/C42,0) -> 0 | D44: =IFERROR(D43/D42,0) -> 0 | E44: =IFERROR(D43/E42,0) -> 0 | F44: =IFERROR(F43/F42,0) -> 0 | G44: =IFERROR(F43/G42,0) -> 0 | H44: =IFERROR(H43/H42,0) -> 0 | I44: =IFERROR(H43/I42,0) -> 0 | J44: =IFERROR(J43/J42,0) -> 0 | K44: =IFERROR(J43/K42,0) -> 0 | L44: =IFERROR(L43/L42,0) -> 0 | M44: =IFERROR(L43/M42,0) -> 0
A45: ~
...

Sheet Field Definitions
B2: PPMS Field Definitions
B4: Project Summary Section
B5: Field | C5: Field Type | D5: Data Source | E5: Formula | F5: System Source
B6: Title | C6: Data | F6: Operations Insights
B7: Date | C7: Data | F7: Operations Insights
B8: Project Name: | C8: Data | F8: Operations Insights
B9: Project Number | C9: Data | F9: Operations Insights | I9: `
B10: Loan/Grant Number: | C10: Data | F10: Operations Insights
B11: Executing/Implementing Agency: | C11: Data | F11: Operations Insights
B12: ADB Administering Unit: | C12: Data | F12: Operations Insights
B13: If TRJM, date of project transfer: | C13: Data | F13: Operations Insights
B14: Sector/Subsector: | C14: Data | F14: Operations Insights
B15: Project Officer: | C15: Data | F15: Operations Insights
B16: Project Analyst: | C16: Data | F16: Operations Insights
B17: Project Document Link: | C17: Data
B18: Project Handover Document Link: | C18: Data
B21: A. Loan/Grant Basic Data
B22: Field | C22: Field Type | D22: Data Source | E22: Formula | F22: System Source
B23: ADB Financing | C23: Formula
B24: Government Financing | C24: Formula
B25: Total ($ million equivalent) | C25: Formula
B26: Product | C26: Data | G26: Multiple Rows
B27: Source | C27: Data | G27: Multiple Rows
B28: Amount | C28: Data | G28: Multiple Rows
B29: Approval | C29: Data | G29: Multiple Rows
B30: Signing | C30: Data | G30: Multiple Rows
B31: Effectivity | C31: Data | G31: Multiple Rows
B32: Closing Original | C32: Data | G32: Multiple Rows
B33: Closing Revised | C33: Data | G33: Multiple Rows
B34: % Elapsed Time | C34: Data | G34: Multiple Rows
B35: Environment Category | C35: Data | G35: Multiple Rows
B36: Involuntary Resettlement Category | C36: Data | G36: Multiple Rows
B37: Indigenous People's Category | C37: Data | G37: Multiple Rows
B38: Gender Category | C38: Data | G38: Multiple Rows
B41: B. Project Rating
B42: Field | C42: Field Type | D42: Data Source | E42: Formula | F42: System Source
B43: Parametrs | C43: Data
B44: Outputs | C44: Data
B45: Contract Awards (%) | C45: Data
B46: Disbursement (%) | C46: Data
...

Sheet List
B1: Countries | D1: Project Rating | E1: Procurement Selection Method | F1: Contract Type | G1: Rating | H1: Weight | I1: FM status | J1: Mission Type | M1: Safeguards Indicator 1 | O1: Safeguards Indicator 2 | Q1: Safeguards Indicator 3 | S1: Safeguards Indicator 4 | U1: Safeguards Indicator 5 | W1: Safeguards Indicator 6 | Y1: Safeguards Indicator 7 | AA1: Safeguards Indicator 8 | AS1: Project Rating | AU1: Outputs (Technical) | AW1: Contract Award and Disbursement | AY1: Financial Management | BA1: Safeguards
A2: AFG | B2: Afghanistan | C2: OT | D2: On Track | E2: ICB 1S1E | F2: Works | G2: Completed, target achieved by ≥85% | H2: 1 | I2: Not Required | J2: Inception | L2: 1 | M2: Not Applicable | N2: On Track | O2: Not Applicable | P2: On Track | Q2: Not Applicable | R2: On Track | S2: Not applicable and/or no clearances required. | T2: On Track | U2: No, all compensations/entitlements have been fully paid prior to displacement as confirmed by relevant ADB-cleared reports, for all project sites with involuntary resettlement impacts. | V2: On Track | W2: Yes, the project meets both criteria (functioning GRM and no CRP-eligible complaint(s) on file). | X2: On Track | Y2: No | Z2: On Track | AA2: Not applicable. Cat C or an FI treated as C. | AB2: On Track | AL2: B. Financial Management Rating | AS2: Average | AT2: Overall Rating | AU2: Overall Weighted Score | AV2: Outputs Rating | AW2: Actual vs. Projected % Difference | AX2: CA&D Rating | AY2: FM Score | AZ2: FM Rating | BA2: Responses | BB2: Safeguards Rating
A3: ARM | B3: Armenia | C3: FA | D3: For Attention | E3: OCB 1S1E | F3: Consulting Services | G3: Completed, target underachieved by ≥16% | H3: 0 | I3: Deferred | J3: Review | L3: 2 | M3: Unknown | N3: For Attention | O3: Unknown | P3: For Attention | Q3: Unknown | R3: For Attention | S3: Not yet due, and/or no works requiring clearances were commenced prior to or during reporting period. | T3: On Track | U3: Not Applicable | V3: On Track | W3: Unknown or no functioning GRM. | X3: For Attention | Y3: Unknown, due to any of the following: (1) external monitor not yet appointed, (2) no recent review mission fielded, (3) monitoring report to base decision on being overdue, (4) Other. | Z3: For Attention | AA3: Yes. Submitted, reporting up to date or is within a grace period of one month. | AB3: On Track | AL3: Indicator | AP3: Score | AQ3: Action Plan if not On Track | AS3: >=90% | AT3: On Track (1.0) | AU3: >=85% | AV3: On Track (1.0) | AW3: >90% | AX3: On Track | AY3: >=75% | AZ3: On Track | BA3: All On Track | BB3: On Track
A4: AZE | B4: Azerbaijan | C4: AR | D4: At Risk | E4: ICB 1S2E | F4: Non-Consulting Services | G4: On track to meet target | H4: 1 | I4: Not yet Due | J4: Special Project Admin | L4: 3 | M4: No, all contracts have been awarded and all include EMPs cleared by ADB and applicable conditions of national EIA/IEE clearance. | N4: On Track | O4: No, all contracts have been awarded after final RPs/DDRs were cleared. | P4: On Track | Q4: No, all contracts have been awarded after final IPPs were cleared. | R4: On Track | S4: Yes, all clearances were obtained for all works commenced prior to or during reporting period. | T4: On Track | U4: Unknown | V4: For Attention | W4: No, the project has an Accountability Mechanism (CRP)-eligible complaint(s) but CAP implementation is on track for full compliance at end of CAP implementation period. | X4: For Attention | Y4: Yes, no time-bound CAP agreed for non-compliance. | Z4: At Risk | AA4: Not yet submitted, reporting is overdue for 12 months or less. | AB4: For Attention | AL4: APFS | AP4: 50 | AQ4: Will improve to OT by _______. {add action plan} | AS4: 65% to <90% | AT4: For Attention (0.7) | AU4: 70% to <85% | AV4: For Attention (0.7) | AW4: 75% to 90% | AX4: For Attention | AY4: 50% to 75% | AZ4: For Attention | BA4: At least one response is For Attention and no At Risk | BB4: For Attention
A5: GEO | B5: Georgia | E5: OCB 1S2E | F5: Goods | G5: On track to meet target, delayed | H5: 0.7 | I5: Yes | J5: Project Completion | L5: 4 | M5: No, not all contracts are awarded. Contracts under bidding incl. EMPs cleared by ADB and applicable conditions of national EIA/IEE clearances. All awarded contracts included EMPs cleared by ADB and any conditions of applicable national EIA/IEE clearance. | N5: On Track | O5: No, not all contracts awarded, with final RPs/DDRs still pending for those contracts. Any awarded contracts meet the requirement of RPs/DDRs being cleared (no other options apply). | P5: On Track | Q5: No, not all contracts awarded, with final IPPs still pending for those contracts. | R5: On Track | S5: Unknown | T5: For Attention | U5: No access is given to sites where compensations are ongoing or pending. | V5: On Track | W5: No, the project has an Accountability Mechanism (CRP)-eligible complaint(s) but CAP still in development or NOT on track for full compliance at end of CAP implementation period. | X5: At Risk | Y5: Yes, still within time-bound CAP. | Z5: On Track | AA5: Not yet submitted or undisclosed, reporting and/or disclosure is overdue for more than 12 months | AB5: For Attention | AL5: AEFS | AP5: 25 | AS5: <65% | AT5: At Risk (0) | AU5: <70% | AV5: At Risk (0) | AW5: <75% | AX5: At Risk | AY5: <50% | AZ5: At Risk | BA5: At least one response is At Risk or an assessment question unanswered | BB5: At Risk
A6: KAZ | B6: Kazakhstan | E6: ICB 2S | F6: EPC | G6: On time, but potential risk of missing target | H6: 0.7 | I6: No | J6: Consultation | L6: 5 | M6: No, not all contracts are awarded. Contracts under bidding do not contain EMPs cleared by ADB and/or any conditions of any national EIA/IEE [explain]. All awarded contracts included EMPs cleared by ADB and any conditions of any national EIA/IEE clearance. | N6: For Attention | O6: Yes, contract(s) have been awarded, with some RPs/DDRs pending to be finalized on a section-by-section basis within a contract package (and no other options apply). | P6: For Attention | Q6: Yes, contracts have been awarded, with some IPPs pending to be finalized on a section-by-section basis. | R6: For Attention | S6: No. National EIA/IEE clearance*** is obtained for project output/component but other clearances missing; time bound corrective action plan is in place to obtain. Plan is 3 months or less overdue. | T6: For Attention | U6: Yes | V6: At Risk | Y6: Yes, implementation of time-bound CAP actions overdue for 3 months or less. | Z6: For Attention | AL6: Compliance with Financial Covenants | AP6: 25 | AW6: Ex. Actual cumulative CA = 10
A7: KGZ | B7: Kyrgyz Republic | E7: OCB 2S | G7: On time, will underachieve target | H7: 0 | J7: Midterm Review | L7: 6 | M7: Yes, awarded contract is turnkey/DBO/EPC** but it includes an outline design-based EMP cleared by ADB and any conditions of any national EIA/IEE clearance. | N7: On Track | O7: Yes, a contract is turnkey/DBO/EPC, and it includes requirements for civil works to be conditional upon clearance of final RPs/DDRs (no other options apply). | P7: On Track | Q7: Yes, a contract turnkey/DBO/EPC but it includes requirements for civil works to be conditional upon clearance of final IPPs. | R7: On Track | S7: No. National EIA/IEE clearance*** is obtained for project output/component but other clearances missing; no time bound corrective action plan in place to obtain them, or corrective action is more than 3 months overdue. | T7: At Risk | U7: Yes, corrective action has been taken, and all compensations are now paid as verified through relevant compliance reports cleared by ADB. | V7: On Track | Y7: Yes, implementation of time-bound CAP actions overdue for more than 3 months. | Z7: At Risk | AL7: Financial Management Rating | AO7: Potential Problem | AW7: Projected CA starting at effectiveness = 12.5
A8: PAK | B8: Pakistan | E8: Shopping | G8: Delayed and potential risk of missing target | H8: 0.7 | L8: 7 | M8: Yes, awarded contract is turnkey/DBO/EPC** but it excludes an outline design-based EMP cleared by ADB and/or any conditions of any national EIA/IEE clearance. | N8: At Risk | O8: Yes, a contract is turnkey/DBO/EPC, but it excludes requirements for civil works to be conditional upon clearance of final RPs. | P8: At Risk | Q8: Yes, a contract turnkey/DBO/EPC but it excludes requirements for civil works to be conditional upon clearance of final IPPs. | R8: At Risk | S8: No. National EIA/IEE clearance*** is missing for any works commenced prior to or during reporting period | T8: At Risk | AW8: % difference = 10/12.5 = 80%
A9: TAJ | B9: Tajikistan | E9: RFQ | G9: Not started, delayed by ≤ 6 months | H9: 0.7 | L9: 8 | M9: Yes, a standard contract was awarded without including EMP cleared by ADB and/or any conditions of any national EIA/IEE clearance. | N9: At Risk | O9: Yes, a standard contract was awarded without ADB’s prior approval of final RP/DDR. | P9: At Risk | Q9: Yes, a standard contract was awarded without ADB’s prior approval of final IPP. | R9: At Risk | S9: Corrective action has been taken, and all clearances for all works commenced prior to or during reporting period have now been obtained. | T9: On Track
A10: TKM | B10: Turkmenistan | E10: Direct Contracting | G10: Not started, delayed by ≥ 7 months | H10: 0 | L10: 9 | M10: Yes, corrective action (by contract variation) has been taken following any contract award to incorporate EMP cleared by ADB and/or any conditions of any national EIA/IEE clearance into contract. | N10: On Track | O10: Yes, corrective action has been taken, and detailed engineering design-based RPs were updated/prepared and cleared after contract award. | P10: On Track | Q10: Yes, corrective action has been taken, and IPPs were updated/prepared and cleared after contract award. | R10: On Track
A11: UZB | B11: Uzbekistan | E11: LCB | G11: Cancelled | H11: 0
A12: REG | B12: Regional | E12: LIB | G12: Not due to start | H12: 1
A13: PRC | B13: PRC | E13: e-Auction
A14: MON | B14: Mongolia | E14: Force Account
E15: QCBS
E16: QBS
E17: CQS
E18: FBS
E19: LCS
E20: ICS
E21: Others
B24: ENV/IR/IP | D24: Gender
B25: A | D25: Gender Equity Theme
B26: B | D26: Effective Gender Mainstreaming
B27: C | D27: Some Gender Benefits
B28: FI | D28: No Gender Elements
H80: =IF(ISBLANK(F100),0,(VLOOKUP(G100,'List'!I13!$G$2:$H$12,2,FALSE))*F100)
